<?xml version="1.0"?>
<robot xmlns:xacro="http://www.ros.org/wiki/xacro">

  <!-- Materials -->
  <material name="white"><color rgba="1 1 1 1"/></material>
  <material name="blue"><color rgba="0.2 0.2 1 1"/></material>
  <material name="black"><color rgba="0 0 0 1"/></material>

  <!-- Base -->
  <link name="base_link"/>

  <!-- BASE_FOOTPRINT LINK -->

    <joint name="base_footprint_joint" type="fixed">
        <parent link="base_link"/>
        <child link="base_footprint"/>
        <origin xyz="0 0 0.3" rpy="0 0 0"/>
    </joint>

    <link name="base_footprint">
    </link>

  <!-- Chassis -->
  <joint name="chassis_joint" type="fixed">
    <parent link="base_link"/>
    <child link="chassis"/>
    <origin xyz="0 0 0.075"/>
  </joint>

  <link name="chassis">
    <visual>
      <geometry><box size="0.3 0.3 0.15"/></geometry>
      <material name="white"/>
    </visual>
    <collision>
      <geometry><box size="0.3 0.3 0.15"/></geometry>
    </collision>
    <inertial>
      <mass value="1.0"/>
      <inertia ixx="0.02" ixy="0" ixz="0"
               iyy="0.02" iyz="0"
               izz="0.02"/>
    </inertial>
  </link>

  <!-- Left wheel -->
  <joint name="left_wheel_joint" type="continuous">
    <parent link="base_link"/>
    <child link="left_wheel"/>
    <origin xyz="0 0.175 0.05" rpy="1.5708 0 0"/>
    <axis xyz="0 0 1"/>
  </joint>

  <link name="left_wheel">
    <visual>
      <geometry><cylinder radius="0.05" length="0.04"/></geometry>
      <material name="blue"/>
    </visual>
    <collision>
      <geometry><cylinder radius="0.05" length="0.04"/></geometry>
    </collision>
    <inertial>
      <mass value="0.1"/>
      <inertia ixx="0.0002" ixy="0" ixz="0"
               iyy="0.0002" iyz="0"
               izz="0.0002"/>
    </inertial>
  </link>

  <!-- Right wheel -->
  <joint name="right_wheel_joint" type="continuous">
    <parent link="base_link"/>
    <child link="right_wheel"/>
    <origin xyz="0 -0.175 0.05" rpy="-1.5708 0 0"/>
    <axis xyz="0 0 1"/>
  </joint>

  <link name="right_wheel">
    <visual>
      <geometry><cylinder radius="0.05" length="0.04"/></geometry>
      <material name="blue"/>
    </visual>
    <collision>
      <geometry><cylinder radius="0.05" length="0.04"/></geometry>
    </collision>
    <inertial>
      <mass value="0.1"/>
      <inertia ixx="0.0002" ixy="0" ixz="0"
               iyy="0.0002" iyz="0"
               izz="0.0002"/>
    </inertial>
  </link>

  <!-- Gazebo Classic Diff Drive Plugin -->
  <gazebo>
    <plugin name="diff_drive" filename="libgazebo_ros_diff_drive.so">
        <update_rate>50</update_rate>
        <left_joint>left_wheel_joint</left_joint>
        <right_joint>right_wheel_joint</right_joint>
        <wheel_separation>0.35</wheel_separation>
        <wheel_diameter>0.10</wheel_diameter>
        <max_wheel_torque>20</max_wheel_torque>
        <command_topic>cmd_vel</command_topic>
        <publish_odom>true</publish_odom>
        <publish_odom_tf>true</publish_odom_tf>
        <publish_wheel_tf>true</publish_wheel_tf>
        <odometry_topic>odom</odometry_topic>
        <odometry_frame>odom</odometry_frame>
        <robot_base_frame>base_link</robot_base_frame>
    </plugin>
  </gazebo>

  <!-- Gazebo properties for chassis -->
  <gazebo reference="chassis">
      <material>Gazebo/White</material>
      <mu1>0.2</mu1>
      <mu2>0.2</mu2>
  </gazebo>

  <!-- Gazebo properties for left wheel -->
  <gazebo reference="left_wheel">
      <material>Gazebo/Blue</material>
      <mu1>100.0</mu1>
      <mu2>100.0</mu2>
      <kp>10000000.0</kp>
      <kd>1.0</kd>
      <fdir1>1 0 0</fdir1>
  </gazebo>

  <!-- Gazebo properties for right wheel -->
  <gazebo reference="right_wheel">
      <material>Gazebo/Blue</material>
      <mu1>100.0</mu1>
      <mu2>100.0</mu2>
      <kp>10000000.0</kp>
      <kd>1.0</kd>
      <fdir1>1 0 0</fdir1>
  </gazebo>

</robot>